Workbook

Sheet Dashboard_6Charts
A1: 个股收益可视化分析包 · 6 Charts Dashboard
A2: 基于 Data_Master 和 Chart_Input_* 表生成；图表可复制到 PPT/Word。
A4: 1. 个股收益排行榜 Top 10 / Bottom 10
A5: Top 10 个股 | B5: 区间涨跌幅 | C5: 行业 | H5: Bottom 10 个股 | I5: 区间涨跌幅 | J5: 行业
A6: 云南锗业 | B6: 0.79579042 | C6: 有色金属 | H6: 科华数据 | I6: -0.47208955 | J6: 电力设备
A7: 东山精密 | B7: 0.76023684 | C7: 电子 | H7: 北信源 | I7: -0.39790576 | J7: 计算机
A8: 宏景科技 | B8: 0.53640043 | C8: 计算机 | H8: 首都在线 | I8: -0.33397007 | J8: 计算机
A9: 海光信息 | B9: 0.51083591 | C9: 电子 | H9: 湖南裕能 | I9: -0.27352321 | J9: 电力设备
A10: 特锐德 | B10: 0.34299191 | C10: 电力设备 | H10: 三生国健 | I10: -0.25970845 | J10: 医药生物
A11: 天赐材料 | B11: 0.32966335 | C11: 电力设备 | H11: 利亚德 | I11: -0.23665893 | J11: 电子
A12: 香农芯创 | B12: 0.2983323 | C12: 电子 | H12: 森特股份 | I12: -0.1704918 | J12: 建筑装饰
A13: 新风光 | B13: 0.28332849 | C13: 电力设备 | H13: 美湖股份 | I13: -0.16153644 | J13: 汽车
A14: 力量钻石 | B14: 0.27477679 | C14: 新材料 | H14: 永福股份 | I14: -0.15779703 | J14: 建筑工程/电力设备
A15: 新锐股份 | B15: 0.26705491 | C15: 机械设备 | H15: 华明装备 | I15: -0.13182674 | J15: 电力设备
A16: 图表解读
A17: - Top 10 平均收益 43.99%。
A18: - Bottom 10 平均收益 -25.96%。
A22: 2. 收益分布图
A23: 收益分布区间 | B23: 股票数量 | L23: 图表解读
A24: <-30% | B24: 3 | L24: - 正收益 28 只，占比 52.83%。
A25: -30~-20% | B25: 3 | L25: - 用于判断收益是否由少数大赢家驱动。
A26: -20~-10% | B26: 13
A27: -10~0% | B27: 6
A28: 0~10% | B28: 11
A29: 10~20% | B29: 7
A30: 20~50% | B30: 6
A31: >50% | B31: 4
A41: 3. 行业大类平均收益
A42: 行业大类（数量） | B42: 平均区间涨跌幅 | C42: 备注 | L42: 图表解读
A43: 机械设备 (2) | B43: 0.23085818 | C43: 样本较少，仅供参考 | L43: - 样本较少行业：机械设备, 家用电器/电子, 传媒, 建筑工程/电力设备, 医药生物, 建筑装饰。
A44: 新材料 (3) | B44: 0.184257 | L44: - 括号内为股票数量。
A45: 有色金属 (4) | B45: 0.17705676
A46: 电子 (13) | B46: 0.12419701
A47: 家用电器/电子 (1) | B47: 0.074733096 | C47: 样本较少，仅供参考
A48: 电力设备 (12) | B48: 0.0012416812
A49: 基础化工 (3) | B49: -0.04656123
A50: 传媒 (1) | B50: -0.063471503 | C50: 样本较少，仅供参考
A51: 汽车 (2) | B51: -0.067338069 | C51: 样本较少，仅供参考
A52: 计算机 (7) | B52: -0.068122655
A53: 建筑装饰 (2) | B53: -0.1477459 | C53: 样本较少，仅供参考
...

Sheet Charts_Copyable
A1: 个股收益可视化分析包 · 图表总览（可直接复制至PPT/Word）
A2: 一、个股收益排行榜
A23: 📌 Top10平均收益 +44.0%，最高为云南锗业(+79.6%)；正收益10支均超+10% | H23: 📌 Bottom10平均收益 -26.0%，集中在计算机/电力设备；最大跌幅科华数据②(-47.2%)
A24: 二、收益分布
A43: 📌 正收益28支(52.8%)，分布偏右尾（少数大涨拉高均值）；-10%~0%区间最多(13支)，说明轻微亏损是主要风险来源
A44: 三、行业大类平均收益
A68: 📌 机械设备/新材料表现最强；计算机/医药/建筑装饰整体偏弱；电力设备覆盖最广(12支)但内部分化大
A69: 四、推荐批次表现趋势
A90: 📌 2月27日、4月8日批次表现最强；3月5-10日和5月18日批次受市场环境影响较大，平均收益为负
A91: 五、收益 × 效率四象限（内部复盘用）
A118: 📌 右上角（高收益+高效率）为最优标的：东山精密、云南锗业等；左下角（亏损+低效率）为重点复盘标的：北信源、科华数据②等

Sheet Opportunity_Review
A1: 个股名称 | B1: 代码 | C1: 区间涨跌幅 | D1: 最高涨幅（%） | E1: 收益回吐 | F1: 行业大类
A2: 科华数据 | B2: 002335 | C2: -0.47208955 | D2: 0.071 | E2: 0.54308955 | F2: 电力设备
A3: 北信源 | B3: 300352 | C3: -0.39790576 | D3: 0.1141 | E3: 0.51200576 | F3: 计算机
A4: 首都在线 | B4: 300846 | C4: -0.33397007 | D4: 0.0432 | E4: 0.37717007 | F4: 计算机
A5: 利亚德 | B5: 300296 | C5: -0.23665893 | D5: 0.0812 | E5: 0.31785893 | F5: 电子
A6: 湖南裕能 | B6: 301358 | C6: -0.27352321 | D6: 0.0156 | E6: 0.28912321 | F6: 电力设备
A7: 三生国健 | B7: 688336 | C7: -0.25970845 | D7: 0.028 | E7: 0.28770845 | F7: 医药生物
A8: 美湖股份 | B8: 603319 | C8: -0.16153644 | D8: 0.0881 | E8: 0.24963644 | F8: 汽车
A9: 安光电 | B9: 600703 | C9: -0.11358314 | D9: 0.1001 | E9: 0.21368314 | F9: 电子
A10: 永福股份 | B10: 300712 | C10: -0.15779703 | D10: 0.0534 | E10: 0.21119703 | F10: 建筑工程/电力设备
A11: 万兴科技 | B11: 300624 | C11: -0.11209366 | D11: 0.0985 | E11: 0.21059366 | F11: 计算机
A12: 湖北宜化 | B12: 000422 | C12: -0.11932129 | D12: 0.0784 | E12: 0.19772129 | F12: 基础化工
A13: 顺网科技 | B13: 300113 | C13: -0.063471503 | D13: 0.1323 | E13: 0.1957715 | F13: 传媒
... A54: 云南锗业 | B54: 002428 | C54: 0.79579042 | D54: 0.1001 | E54: -0.69569042 | F54: 有色金属

Sheet Batch_Summary
A1: 个股推荐日期 | B1: 推荐数量 | C1: 平均区间涨跌幅 | D1: 正收益数量 | E1: 正收益占比 | F1: 最高区间涨跌幅 | G1: 最低区间涨跌幅
A2: 46078 | B2: 3 | C2: 0.040459718 | D2: 3 | E2: 1 | F2: 0.10989957 | G2: 0.0043929712
A3: 46080 | B3: 3 | C3: 0.41916893 | D3: 3 | E3: 1 | F3: 0.79579042 | G3: 0.19466146
A4: 46086 | B4: 2 | C4: -0.10011866 | D4: 0 | E4: 0 | F4: -0.080916031 | G4: -0.11932129
A5: 46087 | B5: 6 | C5: -0.02358876 | D5: 3 | E5: 0.5 | F5: 0.13789174 | G5: -0.23665893
A6: 46091 | B6: 7 | C6: -0.10510752 | D6: 2 | E6: 0.28571429 | F6: 0.016766236 | G6: -0.39790576
A7: 46093 | B7: 3 | C7: -0.077976896 | D7: 1 | E7: 0.33333333 | F7: 0.043109244 | G7: -0.15779703
A8: 46111 | B8: 2 | C8: 0.19510849 | D8: 2 | E8: 1 | F8: 0.32966335 | G8: 0.060553633
A9: 46120 | B9: 3 | C9: 0.52313502 | D9: 3 | E9: 1 | F9: 0.76023684 | G9: 0.2983323
A10: 46126 | B10: 4 | C10: 0.17806046 | D10: 3 | E10: 0.75 | F10: 0.53640043 | G10: -0.11882556
A11: 46127 | B11: 2 | C11: 0.22143572 | D11: 2 | E11: 1 | F11: 0.27477679 | G11: 0.16809466
A12: 46132 | B12: 2 | C12: -0.18700184 | D12: 0 | E12: 0 | F12: -0.11429523 | G12: -0.25970845
A13: 46134 | B13: 2 | C13: 0.025809422 | D13: 2 | E13: 1 | F13: 0.033834586 | G13: 0.017784257
... A18: 46163 | B18: 2 | C18: -0.18657504 | D18: 0 | E18: 0 | F18: -0.099626866 | G18: -0.27352321

Sheet Industry_Summary
A1: 行业大类 | B1: 股票数量 | C1: 平均区间涨跌幅 | D1: 中位数区间涨跌幅 | E1: 正收益数量 | F1: 正收益占比 | G1: 最高区间涨跌幅 | H1: 最低区间涨跌幅
A2: 机械设备 | B2: 2 | C2: 0.23085818 | D2: 0.23085818 | E2: 2 | F2: 1 | G2: 0.26705491 | H2: 0.19466146
A3: 新材料 | B3: 3 | C3: 0.184257 | D3: 0.16809466 | E3: 3 | F3: 1 | G3: 0.27477679 | H3: 0.10989957
A4: 有色金属 | B4: 4 | C4: 0.17705676 | D4: -0.0062894578 | E4: 2 | F4: 0.5 | G4: 0.79579042 | H4: -0.074984443
A5: 电子 | B5: 13 | C5: 0.12419701 | D5: 0.043109244 | E5: 10 | F5: 0.76923077 | G5: 0.76023684 | H5: -0.23665893
A6: 家用电器/电子 | B6: 1 | C6: 0.074733096 | D6: 0.074733096 | E6: 1 | F6: 1 | G6: 0.074733096 | H6: 0.074733096
A7: 电力设备 | B7: 12 | C7: 0.0012416812 | D7: -0.040921305 | E7: 6 | F7: 0.5 | G7: 0.34299191 | H7: -0.47208955
A8: 基础化工 | B8: 3 | C8: -0.04656123 | D8: -0.080916031 | E8: 1 | F8: 0.33333333 | G8: 0.060553633 | H8: -0.11932129
A9: 传媒 | B9: 1 | C9: -0.063471503 | D9: -0.063471503 | E9: 0 | F9: 0 | G9: -0.063471503 | H9: -0.063471503
A10: 汽车 | B10: 2 | C10: -0.067338069 | D10: -0.067338069 | E10: 1 | F10: 0.5 | G10: 0.026860301 | H10: -0.16153644
A11: 计算机 | B11: 7 | C11: -0.068122655 | D11: -0.10438909 | E11: 2 | F11: 0.28571429 | G11: 0.53640043 | H11: -0.39790576
A12: 建筑装饰 | B12: 2 | C12: -0.1477459 | D12: -0.1477459 | E12: 0 | F12: 0 | G12: -0.125 | H12: -0.1704918
A13: 建筑工程/电力设备 | B13: 1 | C13: -0.15779703 | D13: -0.15779703 | E13: 0 | F13: 0 | G13: -0.15779703 | H13: -0.15779703
A14: 医药生物 | B14: 2 | C14: -0.18700184 | D14: -0.18700184 | E14: 0 | F14: 0 | G14: -0.11429523 | H14: -0.25970845

Sheet Top_Bottom
A1: 分组 | B1: 排名 | C1: 个股名称 | D1: 代码 | E1: 区间涨跌幅 | F1: 行业大类
A2: Top 10 | B2: 1 | C2: 云南锗业 | D2: 002428 | E2: 0.79579042 | F2: 有色金属
A3: Top 10 | B3: 2 | C3: 东山精密 | D3: 002384 | E3: 0.76023684 | F3: 电子
A4: Top 10 | B4: 3 | C4: 宏景科技 | D4: 301396 | E4: 0.53640043 | F4: 计算机
A5: Top 10 | B5: 4 | C5: 海光信息 | D5: 688041 | E5: 0.51083591 | F5: 电子
A6: Top 10 | B6: 5 | C6: 特锐德 | D6: 300001 | E6: 0.34299191 | F6: 电力设备
A7: Top 10 | B7: 6 | C7: 天赐材料 | D7: 002709 | E7: 0.32966335 | F7: 电力设备
A8: Top 10 | B8: 7 | C8: 香农芯创 | D8: 300475 | E8: 0.2983323 | F8: 电子
A9: Top 10 | B9: 8 | C9: 新风光 | D9: 688663 | E9: 0.28332849 | F9: 电力设备
A10: Top 10 | B10: 9 | C10: 力量钻石 | D10: 301071 | E10: 0.27477679 | F10: 新材料
A11: Top 10 | B11: 10 | C11: 新锐股份 | D11: 688257 | E11: 0.26705491 | F11: 机械设备
A12: Bottom 10 | B12: 1 | C12: 科华数据 | D12: 002335 | E12: -0.47208955 | F12: 电力设备
A13: Bottom 10 | B13: 2 | C13: 北信源 | D13: 300352 | E13: -0.39790576 | F13: 计算机
... A21: Bottom 10 | B21: 10 | C21: 华明装备 | D21: 002270 | E21: -0.13182674 | F21: 电力设备

Sheet Clean_Data
A1: 序号 | B1: 个股推荐日期 | C1: 个股名称 | D1: 代码 | E1: 推荐日开盘价 | F1: 统计截止日期 | G1: 截止日收盘价 | H1: 区间涨跌幅 | I1: 最高涨幅发生日期 | J1: 最高涨幅（%） | K1: 距推荐日交易天数 | L1: 截止跟踪日 | M1: 原始行业 | N1: 行业大类 | O1: 空字段15
A2: 1 | B2: 46078 | C2: 国瓷材料 | D2: 300285 | E2: 34.85 | F2: 20260507 | G2: 38.68 | H2: 0.10989957 | I2: 46091 | J2: 0.1107 | K2: 10 | L2: 20260507 | M2: 电子陶瓷/电子材料 | N2: 新材料
A3: 2 | B3: 46078 | C3: 风华高科 | D3: 000636 | E3: 25.04 | F3: 20260507 | G3: 25.15 | H3: 0.0043929712 | I3: 46078 | J3: 0.1 | K3: 1 | L3: 20260507 | M3: 被动元件 | N3: 电子
A4: 3 | B4: 46078 | C4: 达利凯普 | D4: 301566 | E4: 25.4 | F4: 20260507 | G4: 25.58 | H4: 0.0070866142 | I4: 46120 | J4: 0.0735 | K4: 30 | L4: 20260507 | M4: 被动元件/射频微波MLCC | N4: 电子
A5: 4 | B5: 46080 | C5: 华锐精密 | D5: 688059 | E5: 122.88 | F5: 20260507 | G5: 146.8 | H5: 0.19466146 | I5: 46141 | J5: 0.1724 | K5: 43 | L5: 20260507 | M5: 数控刀具/硬质合金工具 | N5: 机械设备
A6: 5 | B6: 46080 | C6: 新锐股份 | D6: 688257 | E6: 60.1 | F6: 20260507 | G6: 76.15 | H6: 0.26705491 | I6: 46083 | J6: 0.1497 | K6: 2 | L6: 20260507 | M6: 硬质合金工具 | N6: 机械设备
A7: 6 | B7: 46080 | C7: 云南锗业 | D7: 002428 | E7: 44.66 | F7: 20260507 | G7: 80.2 | H7: 0.79579042 | I7: 46129 | J7: 0.1001 | K7: 35 | L7: 20260507 | M7: 小金属/锗材料 | N7: 有色金属
A8: 7 | B8: 46086 | C8: 华鲁恒升 | D8: 600426 | E8: 39.3 | F8: 20260507 | G8: 36.12 | H8: -0.080916031 | I8: 46119 | J8: 0.0943 | K8: 23 | L8: 20260507 | M8: 煤化工/化学原料 | N8: 基础化工
A9: 8 | B9: 46086 | C9: 湖北宜化 | D9: 000422 | E9: 18.27 | F9: 20260507 | G9: 16.09 | H9: -0.11932129 | I9: 46104 | J9: 0.0784 | K9: 13 | L9: 20260507 | M9: 磷化工/化肥 | N9: 基础化工
A10: 9 | B10: 46087 | C10: 华灿光电 | D10: 300323 | E10: 11.51 | F10: 20260507 | G10: 12.75 | H10: 0.10773241 | I10: 46087 | J10: 0.1649 | K10: 1 | L10: 20260507 | M10: LED芯片 | N10: 电子
A11: 10 | B11: 46087 | C11: 新相微 | D11: 688593 | E11: 35.1 | F11: 20260507 | G11: 39.94 | H11: 0.13789174 | I11: 46149 | J11: 0.1631 | K11: 41 | L11: 20260507 | M11: 显示驱动芯片 | N11: 电子
A12: 11 | B12: 46087 | C12: 利亚德 | D12: 300296 | E12: 8.62 | F12: 20260507 | G12: 6.58 | H12: -0.23665893 | I12: 46120 | J12: 0.0812 | K12: 23 | L12: 20260507 | M12: LED显示 | N12: 电子
A13: 12 | B13: 46087 | C13: 兆驰股份 | D13: 002429 | E13: 11.24 | F13: 20260507 | G13: 12.08 | H13: 0.074733096 | I13: 46094 | J13: 0.1005 | K13: 6 | L13: 20260507 | M13: 显示终端/LED产业链 | N13: 家用电器/电子
... A54: 53 | B54: 46163 | C54: 湖南裕能 | D54: 301358 | E54: 94.8 | F54: 20260611 | G54: 68.87 | H54: -0.27352321 | I54: 46171 | J54: 0.0156 | K54: 7 | L54: 20260619 | M54: 磷酸铁锂正极材料 | N54: 电力设备

Sheet Sheet3

Sheet 假期
A1: holidays
A2: 46023
A3: 46024
A4: 46025
A5: 46068
A6: 46069
A7: 46070
A8: 46071
A9: 46072
A10: 46073
A11: 46074
A12: 46075
A13: 46076
... A34: 46302

Sheet Sheet1
A1: 序号 | B1: 个股推荐日期 | C1: 个股名称 | D1: 代码 | E1: 推荐日开盘价 | F1: 统计截止日期 | G1: 截止日收盘价 | H1: 区间涨跌幅 | I1: 最高涨幅发生日期 | J1: 最高涨幅（%） | K1: 距推荐日交易天数 | L1: 截止跟踪日 | M1: 原始行业 | N1: 行业大类
A2: 1 | B2: 46078 | C2: 国瓷材料 | D2: 300285 | E2: 34.85 | F2: 20260507 | G2: 38.68 | H2: =(G2-E2)/E2 -> 0.10989957 | I2: 46091 | J2: 0.1107 | K2: =NETWORKDAYS(B2,I2,假期!A2:A34) -> 10 | L2: =F2 -> 20260507 | M2: 电子陶瓷/电子材料 | N2: 新材料
A3: 2 | B3: 46078 | C3: 风华高科 | D3: 000636 | E3: 25.04 | F3: 20260507 | G3: 25.15 | H3: =(G3-E3)/E3 -> 0.0043929712 | I3: 46078 | J3: 0.1 | K3: =NETWORKDAYS(B3,I3,假期!A3:A35) -> 1 | L3: =F3 -> 20260507 | M3: 被动元件 | N3: 电子
A4: 3 | B4: 46078 | C4: 达利凯普 | D4: 301566 | E4: 25.4 | F4: 20260507 | G4: 25.58 | H4: =(G4-E4)/E4 -> 0.0070866142 | I4: 46120 | J4: 0.0735 | K4: =NETWORKDAYS(B4,I4,假期!A4:A36) -> 30 | L4: =F4 -> 20260507 | M4: 被动元件/射频微波MLCC | N4: 电子
A5: 4 | B5: 46080 | C5: 华锐精密 | D5: 688059 | E5: 122.88 | F5: 20260507 | G5: 146.8 | H5: =(G5-E5)/E5 -> 0.19466146 | I5: 46141 | J5: 0.1724 | K5: =NETWORKDAYS(B5,I5,假期!A5:A37) -> 43 | L5: =F5 -> 20260507 | M5: 数控刀具/硬质合金工具 | N5: 机械设备
A6: 5 | B6: 46080 | C6: 新锐股份 | D6: 688257 | E6: 60.1 | F6: 20260507 | G6: 76.15 | H6: =(G6-E6)/E6 -> 0.26705491 | I6: 46083 | J6: 0.1497 | K6: =NETWORKDAYS(B6,I6,假期!A6:A38) -> 2 | L6: =F6 -> 20260507 | M6: 硬质合金工具 | N6: 机械设备
A7: 6 | B7: 46080 | C7: 云南锗业 | D7: 002428 | E7: 44.66 | F7: 20260507 | G7: 80.2 | H7: =(G7-E7)/E7 -> 0.79579042 | I7: 46129 | J7: 0.1001 | K7: =NETWORKDAYS(B7,I7,假期!A7:A39) -> 35 | L7: =F7 -> 20260507 | M7: 小金属/锗材料 | N7: 有色金属
A8: 7 | B8: 46086 | C8: 华鲁恒升 | D8: 600426 | E8: 39.3 | F8: 20260507 | G8: 36.12 | H8: =(G8-E8)/E8 -> -0.080916031 | I8: 46119 | J8: 0.0943 | K8: =NETWORKDAYS(B8,I8,假期!A8:A40) -> 23 | L8: =F8 -> 20260507 | M8: 煤化工/化学原料 | N8: 基础化工
A9: 8 | B9: 46086 | C9: 湖北宜化 | D9: 000422 | E9: 18.27 | F9: 20260507 | G9: 16.09 | H9: =(G9-E9)/E9 -> -0.11932129 | I9: 46104 | J9: 0.0784 | K9: =NETWORKDAYS(B9,I9,假期!A9:A41) -> 13 | L9: =F9 -> 20260507 | M9: 磷化工/化肥 | N9: 基础化工
A10: 9 | B10: 46087 | C10: 华灿光电 | D10: 300323 | E10: 11.51 | F10: 20260507 | G10: 12.75 | H10: =(G10-E10)/E10 -> 0.10773241 | I10: 46087 | J10: 0.1649 | K10: =NETWORKDAYS(B10,I10,假期!A10:A42) -> 1 | L10: =F10 -> 20260507 | M10: LED芯片 | N10: 电子
A11: 10 | B11: 46087 | C11: 新相微 | D11: 688593 | E11: 35.1 | F11: 20260507 | G11: 39.94 | H11: =(G11-E11)/E11 -> 0.13789174 | I11: 46149 | J11: 0.1631 | K11: =NETWORKDAYS(B11,I11,假期!A11:A43) -> 41 | L11: =F11 -> 20260507 | M11: 显示驱动芯片 | N11: 电子
A12: 11 | B12: 46087 | C12: 利亚德 | D12: 300296 | E12: 8.62 | F12: 20260507 | G12: 6.58 | H12: =(G12-E12)/E12 -> -0.23665893 | I12: 46120 | J12: 0.0812 | K12: =NETWORKDAYS(B12,I12,假期!A12:A44) -> 23 | L12: =F12 -> 20260507 | M12: LED显示 | N12: 电子
A13: 12 | B13: 46087 | C13: 兆驰股份 | D13: 002429 | E13: 11.24 | F13: 20260507 | G13: 12.08 | H13: =(G13-E13)/E13 -> 0.074733096 | I13: 46094 | J13: 0.1005 | K13: =NETWORKDAYS(B13,I13,假期!A13:A45) -> 6 | L13: =F13 -> 20260507 | M13: 显示终端/LED产业链 | N13: 家用电器/电子
A14: 13 | B14: 46087 | C14: 安光电 | D14: 600703 | E14: 17.08 | F14: 20260507 | G14: 15.14 | H14: =(G14-E14)/E14 -> -0.11358314 | I14: 46134 | J14: 0.1001 | K14: =NETWORKDAYS(B14,I14,假期!A14:A46) -> 33 | L14: =F14 -> 20260507 | M14: LED芯片/化合物半导体 | N14: 电子
A15: 14 | B15: 46087 | C15: 乾照光电 | D15: 300102 | E15: 35.2 | F15: 20260507 | G15: 31.27 | H15: =(G15-E15)/E15 -> -0.11164773 | I15: 46132 | J15: 0.0793 | K15: =NETWORKDAYS(B15,I15,假期!A15:A47) -> 31 | L15: =F15 -> 20260507 | M15: LED芯片 | N15: 电子
A16: 15 | B16: 46091 | C16: 万兴科技 | D16: 300624 | E16: 80.29 | F16: 20260507 | G16: 71.29 | H16: =(G16-E16)/E16 -> -0.11209366 | I16: 46120 | J16: 0.0985 | K16: =NETWORKDAYS(B16,I16,假期!A16:A48) -> 21 | L16: =F16 -> 20260507 | M16: 数字创意软件 | N16: 计算机
A17: 16 | B17: 46091 | C17: 优刻得 | D17: 688158 | E17: 51.89 | F17: 20260507 | G17: 52.76 | H17: =(G17-E17)/E17 -> 0.016766236 | I17: 46120 | J17: 0.1395 | K17: =NETWORKDAYS(B17,I17,假期!A17:A49) -> 22 | L17: =F17 -> 20260507 | M17: 云计算服务 | N17: 计算机
A18: 17 | B18: 46091 | C18: 顺网科技 | D18: 300113 | E18: 30.88 | F18: 20260507 | G18: 28.92 | H18: =(G18-E18)/E18 -> -0.063471503 | I18: 46120 | J18: 0.1323 | K18: =NETWORKDAYS(B18,I18,假期!A18:A50) -> 22 | L18: =F18 -> 20260507 | M18: 互联网服务/游戏服务 | N18: 传媒
A19: 18 | B19: 46091 | C19: 中科创达 | D19: 300496 | E19: 72 | F19: 20260507 | G19: 66.12 | H19: =(G19-E19)/E19 -> -0.081666667 | I19: 46120 | J19: 0.0804 | K19: =NETWORKDAYS(B19,I19,假期!A19:A51) -> 22 | L19: =F19 -> 20260507 | M19: 操作系统软件 | N19: 计算机
A20: 19 | B20: 46091 | C20: 拓维信息 | D20: 002261 | E20: 42.15 | F20: 20260507 | G20: 37.75 | H20: =(G20-E20)/E20 -> -0.10438909 | I20: 46120 | J20: 0.0707 | K20: =NETWORKDAYS(B20,I20,假期!A20:A52) -> 22 | L20: =F20 -> 20260507 | M20: 软件开发/IT服务 | N20: 计算机
A21: 20 | B21: 46091 | C21: 瑞芯微 | D21: 603893 | E21: 179.8 | F21: 20260507 | G21: 181.06 | H21: =(G21-E21)/E21 -> 0.0070077864 | I21: 46120 | J21: 0.0803 | K21: =NETWORKDAYS(B21,I21,假期!A21:A53) -> 22 | L21: =F21 -> 20260507 | M21: 数字芯片设计 | N21: 电子
A22: 21 | B22: 46091 | C22: 北信源 | D22: 300352 | E22: 7.64 | F22: 20260507 | G22: 4.6 | H22: =(G22-E22)/E22 -> -0.39790576 | I22: 46128 | J22: 0.1141 | K22: =NETWORKDAYS(B22,I22,假期!A22:A54) -> 28 | L22: =F22 -> 20260507 | M22: 网络安全软件 | N22: 计算机
A23: 22 | B23: 46093 | C23: 金杯电工 | D23: 002533 | E23: 15.85 | F23: 20260507 | G23: 13.96 | H23: =(G23-E23)/E23 -> -0.1192429 | I23: 46106 | J23: 0.0503 | K23: =NETWORKDAYS(B23,I23,假期!A23:A55) -> 10 | L23: =F23 -> 20260507 | M23: 电线电缆 | N23: 电力设备
A24: 23 | B24: 46093 | C24: 法拉电子 | D24: 600563 | E24: 119 | F24: 20260507 | G24: 124.13 | H24: =(G24-E24)/E24 -> 0.043109244 | I24: 46099 | J24: 0.0823 | K24: =NETWORKDAYS(B24,I24,假期!A24:A56) -> 5 | L24: =F24 -> 20260507 | M24: 薄膜电容 | N24: 电子
A25: 24 | B25: 46093 | C25: 永福股份 | D25: 300712 | E25: 32.32 | F25: 20260507 | G25: 27.22 | H25: =(G25-E25)/E25 -> -0.15779703 | I25: 46105 | J25: 0.0534 | K25: =NETWORKDAYS(B25,I25,假期!A25:A57) -> 9 | L25: =F25 -> 20260507 | M25: 电力工程设计 | N25: 建筑工程/电力设备
A26: 25 | B26: 46111 | C26: 永太科技 | D26: 002326 | E26: 23.12 | F26: 20260507 | G26: 24.52 | H26: =(G26-E26)/E26 -> 0.060553633 | I26: 46126 | J26: 0.0623 | K26: =NETWORKDAYS(B26,I26,假期!A26:A58) -> 12 | L26: =F26 -> 20260507 | M26: 氟化工/精细化工 | N26: 基础化工
A27: 26 | B27: 46111 | C27: 天赐材料 | D27: 002709 | E27: 47.23 | F27: 20260507 | G27: 62.8 | H27: =(G27-E27)/E27 -> 0.32966335 | I27: 46141 | J27: 0.0939 | K27: =NETWORKDAYS(B27,I27,假期!A27:A59) -> 23 | L27: =F27 -> 20260507 | M27: 锂电池电解液材料 | N27: 电力设备
A28: 27 | B28: 46120 | C28: 海光信息 | D28: 688041 | E28: 226.1 | F28: 20260507 | G28: 341.6 | H28: =(G28-E28)/E28 -> 0.51083591 | I28: 46148 | J28: 0.1626 | K28: =NETWORKDAYS(B28,I28,假期!A28:A60) -> 21 | L28: =F28 -> 20260507 | M28: CPU/GPU芯片 | N28: 电子
A29: 28 | B29: 46120 | C29: 东山精密 | D29: 002384 | E29: 119.91 | F29: 20260507 | G29: 211.07 | H29: =(G29-E29)/E29 -> 0.76023684 | I29: 46120 | J29: 0.1 | K29: =NETWORKDAYS(B29,I29,假期!A29:A61) -> 1 | L29: =F29 -> 20260507 | M29: PCB/精密制造 | N29: 电子
A30: 29 | B30: 46120 | C30: 香农芯创 | D30: 300475 | E30: 145.71 | F30: 20260507 | G30: 189.18 | H30: =(G30-E30)/E30 -> 0.2983323 | I30: 46120 | J30: 0.2 | K30: =NETWORKDAYS(B30,I30,假期!A30:A62) -> 1 | L30: =F30 -> 20260507 | M30: 电子元器件分销 | N30: 电子
A31: 30 | B31: 46126 | C31: 欣旺达 | D31: 300207 | E31: 28.95 | F31: 20260514 | G31: 25.51 | H31: =(G31-E31)/E31 -> -0.11882556 | I31: 46141 | J31: 0.0491 | K31: =NETWORKDAYS(B31,I31,假期!A32:A64) -> 12 | L31: 20260514 | M31: 锂电池 | N31: 电力设备
A32: 31 | B32: 46126 | C32: 科华数据 | D32: 002335 | E32: 60.1 | F32: 20260514 | G32: 65.8 | H32: =(G32-E32)/E32 -> 0.09484193 | I32: 46149 | J32: 0.1 | K32: =NETWORKDAYS(B32,I32,假期!A33:A65) -> 18 | L32: 20260514 | M32: 电源设备/数据中心 | N32: 电力设备
A33: 32 | B33: 46126 | C33: 宏景科技 | D33: 301396 | E33: 214.97 | F33: 20260514 | G33: 330.28 | H33: =(G33-E33)/E33 -> 0.53640043 | I33: 46128 | J33: 0.2 | K33: =NETWORKDAYS(B33,I33,假期!A34:A66) -> 3 | L33: 20260514 | M33: 智慧城市IT服务 | N33: 计算机
A34: 33 | B34: 46126 | C34: 协创数据 | D34: 300857 | E34: 240.06 | F34: 20260514 | G34: 288.03 | H34: =(G34-E34)/E34 -> 0.19982504 | I34: 46126 | J34: 0.2 | K34: =NETWORKDAYS(B34,I34,假期!A35:A67) -> 1 | L34: 20260514 | M34: 智能终端制造 | N34: 电子
A35: 34 | B35: 46127 | C35: 力量钻石 | D35: 301071 | E35: 44.8 | F35: 20260515 | G35: 57.11 | H35: =(G35-E35)/E35 -> 0.27477679 | I35: 46155 | J35: 0.094 | K35: =NETWORKDAYS(B35,I35,假期!A36:A68) -> 21 | L35: 20260515 | M35: 培育钻石/超硬材料 | N35: 新材料
A36: 35 | B36: 46127 | C36: 四方达 | D36: 300179 | E36: 24.51 | F36: 20260515 | G36: 28.63 | H36: =(G36-E36)/E36 -> 0.16809466 | I36: 46155 | J36: 0.0747 | K36: =NETWORKDAYS(B36,I36,假期!A37:A69) -> 21 | L36: 20260515 | M36: 超硬材料 | N36: 新材料
A37: 36 | B37: 46132 | C37: 舒泰神 | D37: 300204 | E37: 30.01 | F37: 20260520 | G37: 26.58 | H37: =(G37-E37)/E37 -> -0.11429523 | I37: 46148 | J37: 0.0427 | K37: =NETWORKDAYS(B37,I37,假期!A38:A70) -> 13 | L37: 20260520 | M37: 生物制品/创新药 | N37: 医药生物
A38: 37 | B38: 46132 | C38: 三生国健 | D38: 688336 | E38: 85.75 | F38: 20260520 | G38: 63.48 | H38: =(G38-E38)/E38 -> -0.25970845 | I38: 46153 | J38: 0.028 | K38: =NETWORKDAYS(B38,I38,假期!A39:A71) -> 16 | L38: 20260520 | M38: 抗体药物/生物制品 | N38: 医药生物
A39: 38 | B39: 46134 | C39: 容百科技 | D39: 688005 | E39: 34.3 | F39: 20260522 | G39: 34.91 | H39: =(G39-E39)/E39 -> 0.017784257 | I39: 46148 | J39: 0.0959 | K39: =NETWORKDAYS(B39,I39,假期!A40:A72) -> 11 | L39: 20260522 | M39: 锂电正极材料 | N39: 电力设备
A40: 39 | B40: 46134 | C40: 鼎胜新材 | D40: 603876 | E40: 26.6 | F40: 20260522 | G40: 27.5 | H40: =(G40-E40)/E40 -> 0.033834586 | I40: 46136 | J40: 0.1 | K40: =NETWORKDAYS(B40,I40,假期!A41:A73) -> 3 | L40: 20260522 | M40: 铝加工/电池箔 | N40: 有色金属
...

Sheet Charts_Advanced
A1: 个股收益可视化分析包 · 进阶图表（热力图 / 树图 / 瀑布图 / 雷达图 / 子弹图）
A2: 一、行业 × 批次收益热力图
A36: 📌 热力图能一眼看出哪个行业在哪个时间窗口表现最强。2月27日批次横向全红；3月10日批次多数行业偏绿，是市场环境拖累而非选股问题。
A38: 二、53支个股收益树图
A75: 📌 树图按行业分组、颜色深浅表示收益高低，一张图装下全部53支。颜色越深红=收益越高，越深绿=亏损越大。适合汇报封面。
A77: 三、推荐批次瀑布图
A106: 📌 瀑布图展示每批次收益的正负贡献与累积走势。4月8日批次是最大单次正贡献（+52%均值）；5月18日是最大负贡献（-40%）。
A108: 四、行业选股质量雷达图
A155: 📌 雷达图对比各行业在"平均收益、胜率、效率、样本量"四个维度的相对水平。机械设备综合最优；计算机胜率偏低但有爆发个股。
A157: 五、子弹图：当前收益 vs 最高涨幅
A191: 📌 灰色条=追踪期最高涨幅，彩色条=当前收益，差距越大说明阶段性高点兑现不充分。仅供内部复盘，不代表操作建议。

Sheet Raw_Backup
A1: 序号 | B1: 个股推荐日期 | C1: 个股名称 | D1: 代码 | E1: 推荐日开盘价 | F1: 统计截止日期 | G1: 截止日收盘价 | H1: 区间涨跌幅 | I1: 最高涨幅发生日期 | J1: 最高涨幅（%） | K1: 距推荐日交易天数 | L1: 截止跟踪日 | M1: 原始行业 | N1: 行业大类 | O1: 空字段15
A2: 1 | B2: 46078 | C2: 国瓷材料 | D2: 300285 | E2: 34.85 | F2: 20260507 | G2: 38.68 | H2: 0.10989957 | I2: 46091 | J2: 0.1107 | K2: 10 | L2: 20260507 | M2: 电子陶瓷/电子材料 | N2: 新材料
A3: 2 | B3: 46078 | C3: 风华高科 | D3: 000636 | E3: 25.04 | F3: 20260507 | G3: 25.15 | H3: 0.0043929712 | I3: 46078 | J3: 0.1 | K3: 1 | L3: 20260507 | M3: 被动元件 | N3: 电子
A4: 3 | B4: 46078 | C4: 达利凯普 | D4: 301566 | E4: 25.4 | F4: 20260507 | G4: 25.58 | H4: 0.0070866142 | I4: 46120 | J4: 0.0735 | K4: 30 | L4: 20260507 | M4: 被动元件/射频微波MLCC | N4: 电子
A5: 4 | B5: 46080 | C5: 华锐精密 | D5: 688059 | E5: 122.88 | F5: 20260507 | G5: 146.8 | H5: 0.19466146 | I5: 46141 | J5: 0.1724 | K5: 43 | L5: 20260507 | M5: 数控刀具/硬质合金工具 | N5: 机械设备
A6: 5 | B6: 46080 | C6: 新锐股份 | D6: 688257 | E6: 60.1 | F6: 20260507 | G6: 76.15 | H6: 0.26705491 | I6: 46083 | J6: 0.1497 | K6: 2 | L6: 20260507 | M6: 硬质合金工具 | N6: 机械设备
A7: 6 | B7: 46080 | C7: 云南锗业 | D7: 002428 | E7: 44.66 | F7: 20260507 | G7: 80.2 | H7: 0.79579042 | I7: 46129 | J7: 0.1001 | K7: 35 | L7: 20260507 | M7: 小金属/锗材料 | N7: 有色金属
A8: 7 | B8: 46086 | C8: 华鲁恒升 | D8: 600426 | E8: 39.3 | F8: 20260507 | G8: 36.12 | H8: -0.080916031 | I8: 46119 | J8: 0.0943 | K8: 23 | L8: 20260507 | M8: 煤化工/化学原料 | N8: 基础化工
A9: 8 | B9: 46086 | C9: 湖北宜化 | D9: 000422 | E9: 18.27 | F9: 20260507 | G9: 16.09 | H9: -0.11932129 | I9: 46104 | J9: 0.0784 | K9: 13 | L9: 20260507 | M9: 磷化工/化肥 | N9: 基础化工
A10: 9 | B10: 46087 | C10: 华灿光电 | D10: 300323 | E10: 11.51 | F10: 20260507 | G10: 12.75 | H10: 0.10773241 | I10: 46087 | J10: 0.1649 | K10: 1 | L10: 20260507 | M10: LED芯片 | N10: 电子
A11: 10 | B11: 46087 | C11: 新相微 | D11: 688593 | E11: 35.1 | F11: 20260507 | G11: 39.94 | H11: 0.13789174 | I11: 46149 | J11: 0.1631 | K11: 41 | L11: 20260507 | M11: 显示驱动芯片 | N11: 电子
A12: 11 | B12: 46087 | C12: 利亚德 | D12: 300296 | E12: 8.62 | F12: 20260507 | G12: 6.58 | H12: -0.23665893 | I12: 46120 | J12: 0.0812 | K12: 23 | L12: 20260507 | M12: LED显示 | N12: 电子
A13: 12 | B13: 46087 | C13: 兆驰股份 | D13: 002429 | E13: 11.24 | F13: 20260507 | G13: 12.08 | H13: 0.074733096 | I13: 46094 | J13: 0.1005 | K13: 6 | L13: 20260507 | M13: 显示终端/LED产业链 | N13: 家用电器/电子
A14: 13 | B14: 46087 | C14: 安光电 | D14: 600703 | E14: 17.08 | F14: 20260507 | G14: 15.14 | H14: -0.11358314 | I14: 46134 | J14: 0.1001 | K14: 33 | L14: 20260507 | M14: LED芯片/化合物半导体 | N14: 电子
A15: 14 | B15: 46087 | C15: 乾照光电 | D15: 300102 | E15: 35.2 | F15: 20260507 | G15: 31.27 | H15: -0.11164773 | I15: 46132 | J15: 0.0793 | K15: 31 | L15: 20260507 | M15: LED芯片 | N15: 电子
A16: 15 | B16: 46091 | C16: 万兴科技 | D16: 300624 | E16: 80.29 | F16: 20260507 | G16: 71.29 | H16: -0.11209366 | I16: 46120 | J16: 0.0985 | K16: 21 | L16: 20260507 | M16: 数字创意软件 | N16: 计算机
A17: 16 | B17: 46091 | C17: 优刻得 | D17: 688158 | E17: 51.89 | F17: 20260507 | G17: 52.76 | H17: 0.016766236 | I17: 46120 | J17: 0.1395 | K17: 22 | L17: 20260507 | M17: 云计算服务 | N17: 计算机
A18: 17 | B18: 46091 | C18: 顺网科技 | D18: 300113 | E18: 30.88 | F18: 20260507 | G18: 28.92 | H18: -0.063471503 | I18: 46120 | J18: 0.1323 | K18: 22 | L18: 20260507 | M18: 互联网服务/游戏服务 | N18: 传媒
A19: 18 | B19: 46091 | C19: 中科创达 | D19: 300496 | E19: 72 | F19: 20260507 | G19: 66.12 | H19: -0.081666667 | I19: 46120 | J19: 0.0804 | K19: 22 | L19: 20260507 | M19: 操作系统软件 | N19: 计算机
A20: 19 | B20: 46091 | C20: 拓维信息 | D20: 002261 | E20: 42.15 | F20: 20260507 | G20: 37.75 | H20: -0.10438909 | I20: 46120 | J20: 0.0707 | K20: 22 | L20: 20260507 | M20: 软件开发/IT服务 | N20: 计算机
A21: 20 | B21: 46091 | C21: 瑞芯微 | D21: 603893 | E21: 179.8 | F21: 20260507 | G21: 181.06 | H21: 0.0070077864 | I21: 46120 | J21: 0.0803 | K21: 22 | L21: 20260507 | M21: 数字芯片设计 | N21: 电子
A22: 21 | B22: 46091 | C22: 北信源 | D22: 300352 | E22: 7.64 | F22: 20260507 | G22: 4.6 | H22: -0.39790576 | I22: 46128 | J22: 0.1141 | K22: 28 | L22: 20260507 | M22: 网络安全软件 | N22: 计算机
A23: 22 | B23: 46093 | C23: 金杯电工 | D23: 002533 | E23: 15.85 | F23: 20260507 | G23: 13.96 | H23: -0.1192429 | I23: 46106 | J23: 0.0503 | K23: 10 | L23: 20260507 | M23: 电线电缆 | N23: 电力设备
A24: 23 | B24: 46093 | C24: 法拉电子 | D24: 600563 | E24: 119 | F24: 20260507 | G24: 124.13 | H24: 0.043109244 | I24: 46099 | J24: 0.0823 | K24: 5 | L24: 20260507 | M24: 薄膜电容 | N24: 电子
A25: 24 | B25: 46093 | C25: 永福股份 | D25: 300712 | E25: 32.32 | F25: 20260507 | G25: 27.22 | H25: -0.15779703 | I25: 46105 | J25: 0.0534 | K25: 9 | L25: 20260507 | M25: 电力工程设计 | N25: 建筑工程/电力设备
A26: 25 | B26: 46111 | C26: 永太科技 | D26: 002326 | E26: 23.12 | F26: 20260507 | G26: 24.52 | H26: 0.060553633 | I26: 46126 | J26: 0.0623 | K26: 12 | L26: 20260507 | M26: 氟化工/精细化工 | N26: 基础化工
A27: 26 | B27: 46111 | C27: 天赐材料 | D27: 002709 | E27: 47.23 | F27: 20260507 | G27: 62.8 | H27: 0.32966335 | I27: 46141 | J27: 0.0939 | K27: 23 | L27: 20260507 | M27: 锂电池电解液材料 | N27: 电力设备
A28: 27 | B28: 46120 | C28: 海光信息 | D28: 688041 | E28: 226.1 | F28: 20260507 | G28: 341.6 | H28: 0.51083591 | I28: 46148 | J28: 0.1626 | K28: 21 | L28: 20260507 | M28: CPU/GPU芯片 | N28: 电子
A29: 28 | B29: 46120 | C29: 东山精密 | D29: 002384 | E29: 119.91 | F29: 20260507 | G29: 211.07 | H29: 0.76023684 | I29: 46120 | J29: 0.1 | K29: 1 | L29: 20260507 | M29: PCB/精密制造 | N29: 电子
A30: 29 | B30: 46120 | C30: 香农芯创 | D30: 300475 | E30: 145.71 | F30: 20260507 | G30: 189.18 | H30: 0.2983323 | I30: 46120 | J30: 0.2 | K30: 1 | L30: 20260507 | M30: 电子元器件分销 | N30: 电子
A31: 30 | B31: 46126 | C31: 欣旺达 | D31: 300207 | E31: 28.95 | F31: 20260514 | G31: 25.51 | H31: -0.11882556 | I31: 46141 | J31: 0.0491 | K31: 12 | L31: 20260514 | M31: 锂电池 | N31: 电力设备
A32: 31 | B32: 46126 | C32: 科华数据 | D32: 002335 | E32: 60.1 | F32: 20260514 | G32: 65.8 | H32: 0.09484193 | I32: 46149 | J32: 0.1 | K32: 18 | L32: 20260514 | M32: 电源设备/数据中心 | N32: 电力设备
A33: 32 | B33: 46126 | C33: 宏景科技 | D33: 301396 | E33: 214.97 | F33: 20260514 | G33: 330.28 | H33: 0.53640043 | I33: 46128 | J33: 0.2 | K33: 3 | L33: 20260514 | M33: 智慧城市IT服务 | N33: 计算机
A34: 33 | B34: 46126 | C34: 协创数据 | D34: 300857 | E34: 240.06 | F34: 20260514 | G34: 288.03 | H34: 0.19982504 | I34: 46126 | J34: 0.2 | K34: 1 | L34: 20260514 | M34: 智能终端制造 | N34: 电子
A35: 34 | B35: 46127 | C35: 力量钻石 | D35: 301071 | E35: 44.8 | F35: 20260515 | G35: 57.11 | H35: 0.27477679 | I35: 46155 | J35: 0.094 | K35: 21 | L35: 20260515 | M35: 培育钻石/超硬材料 | N35: 新材料
A36: 35 | B36: 46127 | C36: 四方达 | D36: 300179 | E36: 24.51 | F36: 20260515 | G36: 28.63 | H36: 0.16809466 | I36: 46155 | J36: 0.0747 | K36: 21 | L36: 20260515 | M36: 超硬材料 | N36: 新材料
A37: 36 | B37: 46132 | C37: 舒泰神 | D37: 300204 | E37: 30.01 | F37: 20260520 | G37: 26.58 | H37: -0.11429523 | I37: 46148 | J37: 0.0427 | K37: 13 | L37: 20260520 | M37: 生物制品/创新药 | N37: 医药生物
A38: 37 | B38: 46132 | C38: 三生国健 | D38: 688336 | E38: 85.75 | F38: 20260520 | G38: 63.48 | H38: -0.25970845 | I38: 46153 | J38: 0.028 | K38: 16 | L38: 20260520 | M38: 抗体药物/生物制品 | N38: 医药生物
A39: 38 | B39: 46134 | C39: 容百科技 | D39: 688005 | E39: 34.3 | F39: 20260522 | G39: 34.91 | H39: 0.017784257 | I39: 46148 | J39: 0.0959 | K39: 11 | L39: 20260522 | M39: 锂电正极材料 | N39: 电力设备
A40: 39 | B40: 46134 | C40: 鼎胜新材 | D40: 603876 | E40: 26.6 | F40: 20260522 | G40: 27.5 | H40: 0.033834586 | I40: 46136 | J40: 0.1 | K40: 3 | L40: 20260522 | M40: 铝加工/电池箔 | N40: 有色金属
...

Sheet Data_Master
A1: 序号 | B1: 个股推荐日期 | C1: 个股名称 | D1: 代码 | E1: 区间涨跌幅 | F1: 最高涨幅（%） | G1: 距推荐日交易天数 | H1: 日均收益率 | I1: 原始行业 | J1: 行业大类 | K1: 正收益标识 | L1: 收益分布区间
A2: 1 | B2: 46078 | C2: 国瓷材料 | D2: 300285 | E2: 0.1099 | F2: 0.1107 | G2: 10 | H2: 0.010989957 | I2: 电子陶瓷/电子材料 | J2: 新材料 | K2: TRUE | L2: 10~20%
A3: 2 | B3: 46078 | C3: 风华高科 | D3: 000636 | E3: 0.0043929712 | F3: 0.1 | G3: 1 | H3: 0.0043929712 | I3: 被动元件 | J3: 电子 | K3: TRUE | L3: 0~10%
A4: 3 | B4: 46078 | C4: 达利凯普 | D4: 301566 | E4: 0.0070866142 | F4: 0.0735 | G4: 30 | H4: 0.00023622047 | I4: 被动元件/射频微波MLCC | J4: 电子 | K4: TRUE | L4: 0~10%
A5: 4 | B5: 46080 | C5: 华锐精密 | D5: 688059 | E5: 0.19466146 | F5: 0.1724 | G5: 43 | H5: 0.0045270107 | I5: 数控刀具/硬质合金工具 | J5: 机械设备 | K5: TRUE | L5: 10~20%
A6: 5 | B6: 46080 | C6: 新锐股份 | D6: 688257 | E6: 0.26705491 | F6: 0.1497 | G6: 2 | H6: 0.13352745 | I6: 硬质合金工具 | J6: 机械设备 | K6: TRUE | L6: 20~50%
A7: 6 | B7: 46080 | C7: 云南锗业 | D7: 002428 | E7: 0.79579042 | F7: 0.1001 | G7: 35 | H7: 0.022736869 | I7: 小金属/锗材料 | J7: 有色金属 | K7: TRUE | L7: >50%
A8: 7 | B8: 46086 | C8: 华鲁恒升 | D8: 600426 | E8: -0.080916031 | F8: 0.0943 | G8: 23 | H8: -0.0035180883 | I8: 煤化工/化学原料 | J8: 基础化工 | K8: FALSE | L8: -10~0%
A9: 8 | B9: 46086 | C9: 湖北宜化 | D9: 000422 | E9: -0.11932129 | F9: 0.0784 | G9: 13 | H9: -0.0091785609 | I9: 磷化工/化肥 | J9: 基础化工 | K9: FALSE | L9: -20~-10%
A10: 9 | B10: 46087 | C10: 华灿光电 | D10: 300323 | E10: 0.10773241 | F10: 0.1649 | G10: 1 | H10: 0.10773241 | I10: LED芯片 | J10: 电子 | K10: TRUE | L10: 10~20%
A11: 10 | B11: 46087 | C11: 新相微 | D11: 688593 | E11: 0.13789174 | F11: 0.1631 | G11: 41 | H11: 0.0033632131 | I11: 显示驱动芯片 | J11: 电子 | K11: TRUE | L11: 10~20%
A12: 11 | B12: 46087 | C12: 利亚德 | D12: 300296 | E12: -0.23665893 | F12: 0.0812 | G12: 23 | H12: -0.010289519 | I12: LED显示 | J12: 电子 | K12: FALSE | L12: -30~-20%
A13: 12 | B13: 46087 | C13: 兆驰股份 | D13: 002429 | E13: 0.074733096 | F13: 0.1005 | G13: 6 | H13: 0.012455516 | I13: 显示终端/LED产业链 | J13: 家用电器/电子 | K13: TRUE | L13: 0~10%
... A54: 53 | B54: 46163 | C54: 湖南裕能 | D54: 301358 | E54: -0.27352321 | F54: 0.0156 | G54: 7 | H54: -0.039074744 | I54: 磷酸铁锂正极材料 | J54: 电力设备 | K54: FALSE | L54: -30~-20%

Sheet Chart_Input_Individual
A1: 个股名称 | B1: 代码 | C1: 行业大类 | D1: 区间涨跌幅 | E1: 距推荐日交易天数 | F1: 日均收益率 | G1: 最高涨幅（%） | H1: Top/Bottom 标识 | I1: 是否标注 | J1: 收益分布区间
A2: 云南锗业 | B2: 002428 | C2: 有色金属 | D2: 0.79579042 | E2: 35 | F2: 0.022736869 | G2: 0.1001 | H2: Top 10 | I2: 是 | J2: >50%
A3: 东山精密 | B3: 002384 | C3: 电子 | D3: 0.76023684 | E3: 1 | F3: 0.76023684 | G3: 0.1 | H3: Top 10 | I3: 是 | J3: >50%
A4: 宏景科技 | B4: 301396 | C4: 计算机 | D4: 0.53640043 | E4: 3 | F4: 0.17880014 | G4: 0.2 | H4: Top 10 | I4: 是 | J4: >50%
A5: 海光信息 | B5: 688041 | C5: 电子 | D5: 0.51083591 | E5: 21 | F5: 0.02432552 | G5: 0.1626 | H5: Top 10 | I5: 是 | J5: >50%
A6: 特锐德 | B6: 300001 | C6: 电力设备 | D6: 0.34299191 | E6: 22 | F6: 0.015590542 | G6: 0.1199 | H6: Top 10 | I6: 是 | J6: 20~50%
A7: 天赐材料 | B7: 002709 | C7: 电力设备 | D7: 0.32966335 | E7: 23 | F7: 0.014333189 | G7: 0.0939 | H7: Top 10 | I7: 是 | J7: 20~50%
A8: 香农芯创 | B8: 300475 | C8: 电子 | D8: 0.2983323 | E8: 1 | F8: 0.2983323 | G8: 0.2 | H8: Top 10 | I8: 是 | J8: 20~50%
A9: 新风光 | B9: 688663 | C9: 电力设备 | D9: 0.28332849 | E9: 9 | F9: 0.031480944 | G9: 0.1596 | H9: Top 10 | I9: 是 | J9: 20~50%
A10: 力量钻石 | B10: 301071 | C10: 新材料 | D10: 0.27477679 | E10: 21 | F10: 0.013084609 | G10: 0.094 | H10: Top 10 | I10: 是 | J10: 20~50%
A11: 新锐股份 | B11: 688257 | C11: 机械设备 | D11: 0.26705491 | E11: 2 | F11: 0.13352745 | G11: 0.1497 | H11: Top 10 | I11: 是 | J11: 20~50%
A12: 协创数据 | B12: 300857 | C12: 电子 | D12: 0.19982504 | E12: 1 | F12: 0.19982504 | G12: 0.2 | I12: 是 | J12: 10~20%
A13: 华锐精密 | B13: 688059 | C13: 机械设备 | D13: 0.19466146 | E13: 43 | F13: 0.0045270107 | G13: 0.1724 | J13: 10~20%
A14: 四方达 | B14: 300179 | C14: 新材料 | D14: 0.16809466 | E14: 21 | F14: 0.0080045074 | G14: 0.0747 | J14: 10~20%
A15: 伊戈尔 | B15: 002922 | C15: 电力设备 | D15: 0.16142506 | E15: 12 | F15: 0.013452088 | G15: 0.1 | J15: 10~20%
A16: 新相微 | B16: 688593 | C16: 电子 | D16: 0.13789174 | E16: 41 | F16: 0.0033632131 | G16: 0.1631 | J16: 10~20%
A17: 国瓷材料 | B17: 300285 | C17: 新材料 | D17: 0.10989957 | E17: 10 | F17: 0.010989957 | G17: 0.1107 | J17: 10~20%
A18: 华灿光电 | B18: 300323 | C18: 电子 | D18: 0.10773241 | E18: 1 | F18: 0.10773241 | G18: 0.1649 | J18: 10~20%
A19: 科华数据 | B19: 002335 | C19: 电力设备 | D19: 0.09484193 | E19: 18 | F19: 0.0052689961 | G19: 0.1 | H19: Bottom 10 | I19: 是 | J19: 0~10%
A20: 兆驰股份 | B20: 002429 | C20: 家用电器/电子 | D20: 0.074733096 | E20: 6 | F20: 0.012455516 | G20: 0.1005 | J20: 0~10%
A21: 永太科技 | B21: 002326 | C21: 基础化工 | D21: 0.060553633 | E21: 12 | F21: 0.0050461361 | G21: 0.0623 | J21: 0~10%
A22: 法拉电子 | B22: 600563 | C22: 电子 | D22: 0.043109244 | E22: 5 | F22: 0.0086218487 | G22: 0.0823 | J22: 0~10%
A23: 鼎胜新材 | B23: 603876 | C23: 有色金属 | D23: 0.033834586 | E23: 3 | F23: 0.011278195 | G23: 0.1 | J23: 0~10%
A24: 浙江荣泰 | B24: 603119 | C24: 汽车 | D24: 0.026860301 | E24: 5 | F24: 0.0053720601 | G24: 0.1 | J24: 0~10%
A25: 容百科技 | B25: 688005 | C25: 电力设备 | D25: 0.017784257 | E25: 11 | F25: 0.0016167506 | G25: 0.0959 | J25: 0~10%
A26: 优刻得 | B26: 688158 | C26: 计算机 | D26: 0.016766236 | E26: 22 | F26: 0.00076210165 | G26: 0.1395 | J26: 0~10%
A27: 达利凯普 | B27: 301566 | C27: 电子 | D27: 0.0070866142 | E27: 30 | F27: 0.00023622047 | G27: 0.0735 | J27: 0~10%
A28: 瑞芯微 | B28: 603893 | C28: 电子 | D28: 0.0070077864 | E28: 22 | F28: 0.00031853575 | G28: 0.0803 | J28: 0~10%
A29: 风华高科 | B29: 000636 | C29: 电子 | D29: 0.0043929712 | E29: 1 | F29: 0.0043929712 | G29: 0.1 | J29: 0~10%
A30: 中国铝业 | B30: 601600 | C30: 有色金属 | D30: -0.046413502 | E30: 21 | F30: -0.0022101668 | G30: 0.101 | J30: -10~0%
A31: 顺网科技 | B31: 300113 | C31: 传媒 | D31: -0.063471503 | E31: 22 | F31: -0.0028850683 | G31: 0.1323 | J31: -10~0%
... A34: 中科创达 | B34: 300496 | C34: 计算机 | D34: -0.081666667 | E34: 22 | F34: -0.0037121212 | G34: 0.0804 | J34: -10~0%
A35: 海博思创 | B35: 688411 | C35: 电力设备 | D35: -0.099626866 | E35: 3 | F35: -0.033208955 | G35: 0.0823 | I35: 是 | J35: -10~0%
A36: 拓维信息 | B36: 002261 | C36: 计算机 | D36: -0.10438909 | E36: 22 | F36: -0.0047449585 | G36: 0.0707 | J36: -20~-10%
A37: 乾照光电 | B37: 300102 | C37: 电子 | D37: -0.11164773 | E37: 31 | F37: -0.0036015396 | G37: 0.0793 | J37: -20~-10%
A38: 万兴科技 | B38: 300624 | C38: 计算机 | D38: -0.11209366 | E38: 21 | F38: -0.0053377934 | G38: 0.0985 | J38: -20~-10%
A39: 安光电 | B39: 600703 | C39: 电子 | D39: -0.11358314 | E39: 33 | F39: -0.0034419133 | G39: 0.1001 | J39: -20~-10%
A40: 舒泰神 | B40: 300204 | C40: 医药生物 | D40: -0.11429523 | E40: 13 | F40: -0.0087919411 | G40: 0.0427 | J40: -20~-10%
A41: 欣旺达 | B41: 300207 | C41: 电力设备 | D41: -0.11882556 | E41: 12 | F41: -0.0099021301 | G41: 0.0491 | J41: -20~-10%
A42: 金杯电工 | B42: 002533 | C42: 电力设备 | D42: -0.1192429 | E42: 10 | F42: -0.01192429 | G42: 0.0503 | J42: -20~-10%
...

Sheet Chart_Input_Industry
A1: 行业大类 | B1: 股票数量 | C1: 平均区间涨跌幅 | D1: 中位数区间涨跌幅 | E1: 正收益数量 | F1: 正收益占比 | G1: 最高区间涨跌幅 | H1: 最低区间涨跌幅 | I1: 行业弹性 | J1: 样本备注
A2: 机械设备 | B2: 2 | C2: 0.23085818 | D2: 0.23085818 | E2: 2 | F2: 1 | G2: 0.26705491 | H2: 0.19466146 | I2: 0.07239345 | J2: 样本较少，仅供参考
A3: 新材料 | B3: 3 | C3: 0.184257 | D3: 0.16809466 | E3: 3 | F3: 1 | G3: 0.27477679 | H3: 0.10989957 | I3: 0.16487722
A4: 有色金属 | B4: 4 | C4: 0.17705676 | D4: -0.0062894578 | E4: 2 | F4: 0.5 | G4: 0.79579042 | H4: -0.074984443 | I4: 0.87077486
A5: 电子 | B5: 13 | C5: 0.12419701 | D5: 0.043109244 | E5: 10 | F5: 0.76923077 | G5: 0.76023684 | H5: -0.23665893 | I5: 0.99689578
A6: 家用电器/电子 | B6: 1 | C6: 0.074733096 | D6: 0.074733096 | E6: 1 | F6: 1 | G6: 0.074733096 | H6: 0.074733096 | I6: 0 | J6: 样本较少，仅供参考
A7: 电力设备 | B7: 12 | C7: 0.0012416812 | D7: -0.040921305 | E7: 6 | F7: 0.5 | G7: 0.34299191 | H7: -0.47208955 | I7: 0.81508147
A8: 基础化工 | B8: 3 | C8: -0.04656123 | D8: -0.080916031 | E8: 1 | F8: 0.33333333 | G8: 0.060553633 | H8: -0.11932129 | I8: 0.17987492
A9: 传媒 | B9: 1 | C9: -0.063471503 | D9: -0.063471503 | E9: 0 | F9: 0 | G9: -0.063471503 | H9: -0.063471503 | I9: 0 | J9: 样本较少，仅供参考
A10: 汽车 | B10: 2 | C10: -0.067338069 | D10: -0.067338069 | E10: 1 | F10: 0.5 | G10: 0.026860301 | H10: -0.16153644 | I10: 0.18839674 | J10: 样本较少，仅供参考
A11: 计算机 | B11: 7 | C11: -0.068122655 | D11: -0.10438909 | E11: 2 | F11: 0.28571429 | G11: 0.53640043 | H11: -0.39790576 | I11: 0.93430619
A12: 建筑装饰 | B12: 2 | C12: -0.1477459 | D12: -0.1477459 | E12: 0 | F12: 0 | G12: -0.125 | H12: -0.1704918 | I12: 0.045491803 | J12: 样本较少，仅供参考
A13: 建筑工程/电力设备 | B13: 1 | C13: -0.15779703 | D13: -0.15779703 | E13: 0 | F13: 0 | G13: -0.15779703 | H13: -0.15779703 | I13: 0 | J13: 样本较少，仅供参考
A14: 医药生物 | B14: 2 | C14: -0.18700184 | D14: -0.18700184 | E14: 0 | F14: 0 | G14: -0.11429523 | H14: -0.25970845 | I14: 0.14541322 | J14: 样本较少，仅供参考

Sheet Chart_Input_Batch
A1: 个股推荐日期 | B1: 推荐数量 | C1: 平均区间涨跌幅 | D1: 正收益数量 | E1: 正收益占比 | F1: 批次贡献 | G1: 贡献方向 | H1: 累计贡献
A2: 46078 | B2: 3 | C2: 0.040459718 | D2: 3 | E2: 1 | F2: 0.0022901727 | G2: 正贡献 | H2: 0.0022901727
A3: 46080 | B3: 3 | C3: 0.41916893 | D3: 3 | E3: 1 | F3: 0.023726543 | G3: 正贡献 | H3: 0.026016716
A4: 46086 | B4: 2 | C4: -0.10011866 | D4: 0 | E4: 0 | F4: -0.0037780627 | G4: 负贡献 | H4: 0.022238653
A5: 46087 | B5: 6 | C5: -0.02358876 | D5: 3 | E5: 0.5 | F5: -0.0026704256 | G5: 负贡献 | H5: 0.019568228
A6: 46091 | B6: 7 | C6: -0.10510752 | D6: 2 | E6: 0.28571429 | F6: -0.013882126 | G6: 负贡献 | H6: 0.005686102
A7: 46093 | B7: 3 | C7: -0.077976896 | D7: 1 | E7: 0.33333333 | F7: -0.0044137866 | G7: 负贡献 | H7: 0.0012723154
A8: 46111 | B8: 2 | C8: 0.19510849 | D8: 2 | E8: 1 | F8: 0.0073625846 | G8: 正贡献 | H8: 0.0086349
A9: 46120 | B9: 3 | C9: 0.52313502 | D9: 3 | E9: 1 | F9: 0.029611416 | G9: 正贡献 | H9: 0.038246316
A10: 46126 | B10: 4 | C10: 0.17806046 | D10: 3 | E10: 0.75 | F10: 0.013438525 | G10: 正贡献 | H10: 0.051684842
A11: 46127 | B11: 2 | C11: 0.22143572 | D11: 2 | E11: 1 | F11: 0.0083560649 | G11: 正贡献 | H11: 0.060040906
A12: 46132 | B12: 2 | C12: -0.18700184 | D12: 0 | E12: 0 | F12: -0.0070566734 | G12: 负贡献 | H12: 0.052984233
A13: 46134 | B13: 2 | C13: 0.025809422 | D13: 2 | E13: 1 | F13: 0.00097394043 | G13: 正贡献 | H13: 0.053958174
... A18: 46163 | B18: 2 | C18: -0.18657504 | D18: 0 | E18: 0 | F18: -0.0070405674 | G18: 负贡献 | H18: 0.033677855

Sheet Summary_KPI
A1: 指标 | B1: 数值 | C1: 说明
A2: 股票总数 | B2: 53 | C2: Data_Master 中可计算收益的股票数量
A3: 平均区间涨跌幅 | B3: 0.033677855 | C3: 等权平均收益
A4: 中位数区间涨跌幅 | B4: 0.0070077864 | C4: 中位表现
A5: 正收益股票数量 | B5: 28 | C5: 区间涨跌幅 > 0
A6: 正收益占比 | B6: 0.52830189 | C6: 正收益股票数量 / 股票总数
A7: Top 10 平均收益 | B7: 0.43994114 | C7: 个股收益前10名平均
A8: Bottom 10 平均收益 | B8: -0.2595508 | C8: 个股收益后10名平均
A9: 最佳个股 | B9: 云南锗业 (79.58%) | C9: 区间涨跌幅最高
A10: 最弱个股 | B10: 科华数据 (-47.21%) | C10: 区间涨跌幅最低
A11: 最强行业 | B11: 机械设备 (23.09%) | C11: 行业平均收益最高
A12: 最弱行业 | B12: 医药生物 (-18.70%) | C12: 行业平均收益最低

Sheet Readme
A1: 模块 | B1: 说明
A2: 数据口径 | B2: 以 Clean_Data 的显示值为基础重建 Data_Master；Sheet1 原始数据另存 Raw_Backup 并隐藏。
A3: Data_Master | B3: 只保留 6 张图需要的核心字段，并新增日均收益率、正收益标识、收益分布区间。
A4: Chart_Input_Individual | B4: 支持 Top/Bottom、收益分布、收益×效率四象限图。仅关键个股建议标注，避免散点图拥挤。
A5: Chart_Input_Industry | B5: 支持行业平均收益和行业四维气泡图；n=1 或 n=2 标记为样本较少，仅供参考。
A6: Chart_Input_Batch | B6: 批次贡献 = 推荐数量 / 总股票数 × 平均区间涨跌幅；累计贡献用于瀑布图。
A7: Dashboard_6Charts | B7: 包含 6 个可复制图表/图表区：排行榜、分布、行业平均、效率四象限、批次贡献、行业气泡。
A8: 颜色 | B8: 红色=正收益/正贡献，绿色=负收益/负贡献，蓝色=总体或中性信息。
A9: 注意 | B9: 瀑布图使用内部数据构造的贡献图表；如需 Excel 365 原生 Waterfall，可用 Chart_Input_Batch 一键重插。
